Workbook

Sheet 연간시즌표
B2: ■'26년도 시즌
B4: 합계 | C4: 25년 | M4: 26년
C5: 3월 | D5: 4월 | E5: 5월 | F5: 6월 | G5: 7월 | H5: 8월 | I5: 9월 | J5: 10월 | K5: 11월 | L5: 12월 | M5: 1월 | N5: 2월
B6: 연휴 및성수기 | C6: 3.1(일) | E6: 5.1(금)-5.4(월) 5.22(금)-5.24(일) | F6: 6.5(금)-6.6(토) | G6: 여름성수기7.17(금)-7.31(금) | H6: 여름성수기8.1(토)-8.22(토) | I6: 9.23(수)-9.26(토) | J6: 10.2(금)-10.4(일) 10.8(목)-10.10(토) | L6: 12.24(목)-12.26(토) 12.31(목) | M6: 1.1(금)-1.2(토) | N6: 2.5(금)-2.8(월)
C7: 3.1절 연휴 | E7: 어린이날 연휴 석가탄신일 연휴 | F7: 현충일연휴 | G7: 여름 성수기 | I7: 추석연휴 | J7: 개천절연휴 한글날 연휴 | L7: 겨울성수기
B8: 준주말 | G8: 7.16(목) | O8: * 공휴일 전일 준주말 적용
B10: 3월
B12: 구분 | C12: 46082 | D12: 46083 | E12: 46084 | F12: 46085 | G12: 46086 | H12: 46087 | I12: 46088 | J12: 46089 | K12: 46090 | L12: 46091 | M12: 46092 | N12: 46093 | O12: 46094 | P12: 46095 | Q12: 46096 | R12: 46097 | S12: 46098 | T12: 46099 | U12: 46100 | V12: 46101 | W12: 46102 | X12: 46103 | Y12: 46104 | Z12: 46105 | AA12: 46106 | AB12: 46107 | AC12: 46108 | AD12: 46109 | AE12: 46110 | AF12: 46111 | AG12: 46112
C13: =C12 -> 46082 | D13: =D12 -> 46083 | E13: =E12 -> 46084 | F13: =F12 -> 46085 | G13: =G12 -> 46086 | H13: =H12 -> 46087 | I13: =I12 -> 46088 | J13: =J12 -> 46089 | ... AG13: =AG12 -> 46112
B14: 쏘라노 | C14: ='3월(무기명)'!D4 -> 봄 극성수기 연휴 | D14: ='3월(무기명)'!E4 -> 봄 비수기 월요일 | E14: ='3월(무기명)'!F4 -> 봄 비수기 화요일 | F14: ='3월(무기명)'!G4 -> 봄 비수기 수요일 | G14: ='3월(무기명)'!H4 -> 봄 비수기 목요일 | H14: ='3월(무기명)'!I4 -> 봄 비수기 준주말 | I14: ='3월(무기명)'!J4 -> 봄 비수기 주말 | J14: ='3월(무기명)'!K4 -> 봄 비수기 일요일 | ... AG14: ='3월(무기명)'!AH4 -> 봄 비수기 화요일
B15: 설악별관 | C15: =C14 -> 봄 극성수기 연휴 | D15: =D14 -> 봄 비수기 월요일 | E15: =E14 -> 봄 비수기 화요일 | F15: =F14 -> 봄 비수기 수요일 | G15: =G14 -> 봄 비수기 목요일 | H15: =H14 -> 봄 비수기 준주말 | I15: =I14 -> 봄 비수기 주말 | J15: =J14 -> 봄 비수기 일요일 | ... AG15: =AG14 -> 봄 비수기 화요일
B16: 용인 | C16: =C15 -> 봄 극성수기 연휴 | D16: =D15 -> 봄 비수기 월요일 | E16: =E15 -> 봄 비수기 화요일 | F16: =F15 -> 봄 비수기 수요일 | G16: =G15 -> 봄 비수기 목요일 | H16: =H15 -> 봄 비수기 준주말 | I16: =I15 -> 봄 비수기 주말 | J16: =J15 -> 봄 비수기 일요일 | ... AG16: =AG15 -> 봄 비수기 화요일
B17: 산정호수 | C17: =C16 -> 봄 극성수기 연휴 | D17: =D16 -> 봄 비수기 월요일 | E17: =E16 -> 봄 비수기 화요일 | F17: =F16 -> 봄 비수기 수요일 | G17: =G16 -> 봄 비수기 목요일 | H17: =H16 -> 봄 비수기 준주말 | I17: =I16 -> 봄 비수기 주말 | J17: =J16 -> 봄 비수기 일요일 | ... AG17: =AG16 -> 봄 비수기 화요일
B18: 해운대 | C18: =C17 -> 봄 극성수기 연휴 | D18: =D17 -> 봄 비수기 월요일 | E18: =E17 -> 봄 비수기 화요일 | F18: =F17 -> 봄 비수기 수요일 | G18: =G17 -> 봄 비수기 목요일 | H18: =H17 -> 봄 비수기 준주말 | I18: =I17 -> 봄 비수기 주말 | J18: =J17 -> 봄 비수기 일요일 | ... AG18: =AG17 -> 봄 비수기 화요일
B19: 대천 | C19: =C18 -> 봄 극성수기 연휴 | D19: =D18 -> 봄 비수기 월요일 | E19: =E18 -> 봄 비수기 화요일 | F19: =F18 -> 봄 비수기 수요일 | G19: =G18 -> 봄 비수기 목요일 | H19: =H18 -> 봄 비수기 준주말 | I19: =I18 -> 봄 비수기 주말 | J19: =J18 -> 봄 비수기 일요일 | ... AG19: =AG18 -> 봄 비수기 화요일
B20: 경주 | C20: =C19 -> 봄 극성수기 연휴 | D20: =D19 -> 봄 비수기 월요일 | E20: =E19 -> 봄 비수기 화요일 | F20: =F19 -> 봄 비수기 수요일 | G20: =G19 -> 봄 비수기 목요일 | H20: =H19 -> 봄 비수기 준주말 | I20: =I19 -> 봄 비수기 주말 | J20: =J19 -> 봄 비수기 일요일 | ... AG20: =AG19 -> 봄 비수기 화요일
B21: 제주 | C21: =C20 -> 봄 극성수기 연휴 | D21: =D20 -> 봄 비수기 월요일 | E21: =E20 -> 봄 비수기 화요일 | F21: =F20 -> 봄 비수기 수요일 | G21: =G20 -> 봄 비수기 목요일 | H21: =H20 -> 봄 비수기 준주말 | I21: =I20 -> 봄 비수기 주말 | J21: =J20 -> 봄 비수기 일요일 | ... AG21: =AG20 -> 봄 비수기 화요일
B22: 평창 | C22: =C21 -> 봄 극성수기 연휴 | D22: =D21 -> 봄 비수기 월요일 | E22: =E21 -> 봄 비수기 화요일 | F22: =F21 -> 봄 비수기 수요일 | G22: =G21 -> 봄 비수기 목요일 | H22: =H21 -> 봄 비수기 준주말 | I22: =I21 -> 봄 비수기 주말 | J22: =J21 -> 봄 비수기 일요일 | ... AG22: =AG21 -> 봄 비수기 화요일
B23: 벨버디어 | C23: =C22 -> 봄 극성수기 연휴 | D23: =D22 -> 봄 비수기 월요일 | E23: =E22 -> 봄 비수기 화요일 | F23: =F22 -> 봄 비수기 수요일 | G23: =G22 -> 봄 비수기 목요일 | H23: =H22 -> 봄 비수기 준주말 | I23: =I22 -> 봄 비수기 주말 | J23: =J22 -> 봄 비수기 일요일 | ... AG23: =AG22 -> 봄 비수기 화요일
B24: 르 씨엘 | C24: =C23 -> 봄 극성수기 연휴 | D24: =D23 -> 봄 비수기 월요일 | E24: =E23 -> 봄 비수기 화요일 | F24: =F23 -> 봄 비수기 수요일 | G24: =G23 -> 봄 비수기 목요일 | H24: =H23 -> 봄 비수기 준주말 | I24: =I23 -> 봄 비수기 주말 | J24: =J23 -> 봄 비수기 일요일 | ... AG24: =AG23 -> 봄 비수기 화요일
B25: 여수 벨메르 | C25: =C24 -> 봄 극성수기 연휴 | D25: =D24 -> 봄 비수기 월요일 | E25: =E24 -> 봄 비수기 화요일 | F25: =F24 -> 봄 비수기 수요일 | G25: =G24 -> 봄 비수기 목요일 | H25: =H24 -> 봄 비수기 준주말 | I25: =I24 -> 봄 비수기 주말 | J25: =J24 -> 봄 비수기 일요일 | ... AG25: =AG24 -> 봄 비수기 화요일
B27: 4월
B29: 구분 | C29: 46113 | D29: 46114 | E29: 46115 | F29: 46116 | G29: 46117 | H29: 46118 | I29: 46119 | J29: 46120 | K29: 46121 | L29: 46122 | M29: 46123 | N29: 46124 | O29: 46125 | P29: 46126 | Q29: 46127 | R29: 46128 | S29: 46129 | T29: 46130 | U29: 46131 | V29: 46132 | W29: 46133 | X29: 46134 | Y29: 46135 | Z29: 46136 | AA29: 46137 | AB29: 46138 | AC29: 46139 | AD29: 46140 | AE29: 46141 | AF29: 46142
C30: =C29 -> 46113 | D30: =D29 -> 46114 | E30: =E29 -> 46115 | F30: =F29 -> 46116 | G30: =G29 -> 46117 | H30: =H29 -> 46118 | I30: =I29 -> 46119 | J30: =J29 -> 46120 | ... AF30: =AF29 -> 46142
B31: 쏘라노 | C31: ='4월(무기명)'!D21 -> 봄 비수기 수요일 | D31: ='4월(무기명)'!E21 -> 봄 비수기 목요일 | E31: ='4월(무기명)'!F21 -> 봄 비수기 준주말 | F31: ='4월(무기명)'!G21 -> 봄 비수기 주말 | G31: ='4월(무기명)'!H21 -> 봄 비수기 일요일 | H31: ='4월(무기명)'!I21 -> 봄 비수기 월요일 | I31: ='4월(무기명)'!J21 -> 봄 비수기 화요일 | J31: ='4월(무기명)'!K21 -> 봄 비수기 수요일 | ... AF31: ='4월(무기명)'!AG21 -> 봄 비수기 목요일
B32: 설악별관 | C32: =C31 -> 봄 비수기 수요일 | D32: =D31 -> 봄 비수기 목요일 | E32: =E31 -> 봄 비수기 준주말 | F32: =F31 -> 봄 비수기 주말 | G32: =G31 -> 봄 비수기 일요일 | H32: =H31 -> 봄 비수기 월요일 | I32: =I31 -> 봄 비수기 화요일 | J32: =J31 -> 봄 비수기 수요일 | ... AF32: =AF31 -> 봄 비수기 목요일
B33: 용인 | C33: =C32 -> 봄 비수기 수요일 | D33: =D32 -> 봄 비수기 목요일 | E33: =E32 -> 봄 비수기 준주말 | F33: =F32 -> 봄 비수기 주말 | G33: =G32 -> 봄 비수기 일요일 | H33: =H32 -> 봄 비수기 월요일 | I33: =I32 -> 봄 비수기 화요일 | J33: =J32 -> 봄 비수기 수요일 | ... AF33: =AF32 -> 봄 비수기 목요일
B34: 산정호수 | C34: =C33 -> 봄 비수기 수요일 | D34: =D33 -> 봄 비수기 목요일 | E34: =E33 -> 봄 비수기 준주말 | F34: =F33 -> 봄 비수기 주말 | G34: =G33 -> 봄 비수기 일요일 | H34: =H33 -> 봄 비수기 월요일 | I34: =I33 -> 봄 비수기 화요일 | J34: =J33 -> 봄 비수기 수요일 | ... AF34: =AF33 -> 봄 비수기 목요일
B35: 해운대 | C35: =C34 -> 봄 비수기 수요일 | D35: =D34 -> 봄 비수기 목요일 | E35: =E34 -> 봄 비수기 준주말 | F35: =F34 -> 봄 비수기 주말 | G35: =G34 -> 봄 비수기 일요일 | H35: =H34 -> 봄 비수기 월요일 | I35: =I34 -> 봄 비수기 화요일 | J35: =J34 -> 봄 비수기 수요일 | ... AF35: =AF34 -> 봄 비수기 목요일
B36: 대천 | C36: =C35 -> 봄 비수기 수요일 | D36: =D35 -> 봄 비수기 목요일 | E36: =E35 -> 봄 비수기 준주말 | F36: =F35 -> 봄 비수기 주말 | G36: =G35 -> 봄 비수기 일요일 | H36: =H35 -> 봄 비수기 월요일 | I36: =I35 -> 봄 비수기 화요일 | J36: =J35 -> 봄 비수기 수요일 | ... AF36: =AF35 -> 봄 비수기 목요일
B37: 경주 | C37: =C36 -> 봄 비수기 수요일 | D37: =D36 -> 봄 비수기 목요일 | E37: =E36 -> 봄 비수기 준주말 | F37: =F36 -> 봄 비수기 주말 | G37: =G36 -> 봄 비수기 일요일 | H37: =H36 -> 봄 비수기 월요일 | I37: =I36 -> 봄 비수기 화요일 | J37: =J36 -> 봄 비수기 수요일 | ... AF37: =AF36 -> 봄 비수기 목요일
B38: 제주 | C38: =C37 -> 봄 비수기 수요일 | D38: =D37 -> 봄 비수기 목요일 | E38: =E37 -> 봄 비수기 준주말 | F38: =F37 -> 봄 비수기 주말 | G38: =G37 -> 봄 비수기 일요일 | H38: =H37 -> 봄 비수기 월요일 | I38: =I37 -> 봄 비수기 화요일 | J38: =J37 -> 봄 비수기 수요일 | ... AF38: =AF37 -> 봄 비수기 목요일
B39: 평창 | C39: =C38 -> 봄 비수기 수요일 | D39: =D38 -> 봄 비수기 목요일 | E39: =E38 -> 봄 비수기 준주말 | F39: =F38 -> 봄 비수기 주말 | G39: =G38 -> 봄 비수기 일요일 | H39: =H38 -> 봄 비수기 월요일 | I39: =I38 -> 봄 비수기 화요일 | J39: =J38 -> 봄 비수기 수요일 | ... AF39: =AF38 -> 봄 비수기 목요일
B40: 벨버디어 | C40: =C39 -> 봄 비수기 수요일 | D40: =D39 -> 봄 비수기 목요일 | E40: =E39 -> 봄 비수기 준주말 | F40: =F39 -> 봄 비수기 주말 | G40: =G39 -> 봄 비수기 일요일 | H40: =H39 -> 봄 비수기 월요일 | I40: =I39 -> 봄 비수기 화요일 | J40: =J39 -> 봄 비수기 수요일 | ... AF40: =AF39 -> 봄 비수기 목요일
B41: 르 씨엘 | C41: =C40 -> 봄 비수기 수요일 | D41: =D40 -> 봄 비수기 목요일 | E41: =E40 -> 봄 비수기 준주말 | F41: =F40 -> 봄 비수기 주말 | G41: =G40 -> 봄 비수기 일요일 | H41: =H40 -> 봄 비수기 월요일 | I41: =I40 -> 봄 비수기 화요일 | J41: =J40 -> 봄 비수기 수요일 | ... AF41: =AF40 -> 봄 비수기 목요일
B42: 여수 벨메르 | C42: =C41 -> 봄 비수기 수요일 | D42: =D41 -> 봄 비수기 목요일 | E42: =E41 -> 봄 비수기 준주말 | F42: =F41 -> 봄 비수기 주말 | G42: =G41 -> 봄 비수기 일요일 | H42: =H41 -> 봄 비수기 월요일 | I42: =I41 -> 봄 비수기 화요일 | J42: =J41 -> 봄 비수기 수요일 | ... AF42: =AF41 -> 봄 비수기 목요일
B44: 5월
B46: 구분 | C46: 46143 | D46: 46144 | E46: 46145 | F46: 46146 | G46: 46147 | H46: 46148 | I46: 46149 | J46: 46150 | K46: 46151 | L46: 46152 | M46: 46153 | N46: 46154 | O46: 46155 | P46: 46156 | Q46: 46157 | R46: 46158 | S46: 46159 | T46: 46160 | U46: 46161 | V46: 46162 | W46: 46163 | X46: 46164 | Y46: 46165 | Z46: 46166 | AA46: 46167 | AB46: 46168 | AC46: 46169 | AD46: 46170 | AE46: 46171 | AF46: 46172 | AG46: 46173
C47: 46143 | D47: 46144 | E47: 46145 | F47: 46146 | G47: 46147 | H47: 46148 | I47: 46149 | J47: 46150 | K47: 46151 | L47: 46152 | M47: 46153 | N47: 46154 | O47: 46155 | P47: 46156 | Q47: 46157 | R47: 46158 | S47: 46159 | T47: 46160 | U47: 46161 | V47: 46162 | W47: 46163 | X47: 46164 | Y47: 46165 | Z47: 46166 | AA47: 46167 | AB47: 46168 | AC47: 46169 | AD47: 46170 | AE47: 46171 | AF47: 46172 | AG47: 일
B48: 쏘라노 | C48: 봄 극성수기 연휴 | D48: 봄 극성수기 연휴 | E48: 봄 극성수기 연휴 | F48: 봄 극성수기 연휴 | G48: 봄 비수기 화요일 | H48: 봄 비수기 수요일 | I48: 봄 비수기 목요일 | J48: 봄 비수기 준주말 | K48: 봄 비수기 주말 | L48: 봄 비수기 일요일 | M48: 봄 비수기 월요일 | N48: 봄 비수기 화요일 | O48: 봄 비수기 수요일 | P48: 봄 비수기 목요일 | Q48: 봄 비수기 준주말 | R48: 봄 비수기 주말 | S48: 봄 비수기 일요일 | T48: 봄 비수기 월요일 | U48: 봄 비수기 화요일 | V48: 봄 비수기 수요일 | W48: 봄 비수기 목요일 | X48: 봄 극성수기 연휴 | Y48: 봄 극성수기 연휴 | Z48: 봄 극성수기 연휴 | AA48: 봄 비수기 월요일 | AB48: 봄 비수기 화요일 | AC48: 봄 비수기 수요일 | AD48: 봄 비수기 목요일 | AE48: 봄 비수기 준주말 | AF48: 봄 비수기 주말 | AG48: 봄 비수기 일요일
...

Sheet 회원요금기준▶
B2: 회원구분 | D2: 무기명회원권 | E2: 기명회원권
B3: 구분 | D3: 무기명 | E3: 기명 | F3: 회원추천
B4: 시즌 | C4: 기준 | D4: - | E4: 무기명가 대비 | F4: 무기명가 대비
B5: 비수기 | C5: 주중 | D5: 월별요금적용 | E5: -10000 | F5: 3000
C6: 준주말 | F6: 3000
C7: 주말 | F7: 15000
B8: 여름/겨울/연휴 | C8: 준성수기B | F8: 3000
C9: 준성수기A | F9: 3000
C10: 성수기 | F10: 15000
C11: 극성수기 | F11: 15000

Sheet 3월(무기명)
A1: ■ 2026년 3월 - 무기명
A2: 영업장명 | B2: 객실타입 | C2: 객실명 | D2: 46082 | E2: 46083 | F2: 46084 | G2: 46085 | H2: 46086 | I2: 46087 | J2: 46088 | K2: 46089 | L2: 46090 | M2: 46091 | N2: 46092 | O2: 46093 | P2: 46094 | Q2: 46095 | R2: 46096 | S2: 46097 | T2: 46098 | U2: 46099 | V2: 46100 | W2: 46101 | X2: 46102 | Y2: 46103 | Z2: 46104 | AA2: 46105 | AB2: 46106 | AC2: 46107 | AD2: 46108 | AE2: 46109 | AF2: 46110 | AG2: 46111 | AH2: 46112
D3: =D2 -> 46082 | E3: =E2 -> 46083 | F3: =F2 -> 46084 | G3: =G2 -> 46085 | H3: =H2 -> 46086 | I3: =I2 -> 46087 | J3: =J2 -> 46088 | K3: =K2 -> 46089 | ... AH3: =AH2 -> 46112
D4: 봄 극성수기 연휴 | E4: 봄 비수기 월요일 | F4: 봄 비수기 화요일 | G4: 봄 비수기 수요일 | H4: 봄 비수기 목요일 | I4: 봄 비수기 준주말 | J4: 봄 비수기 주말 | K4: 봄 비수기 일요일 | L4: 봄 비수기 월요일 | M4: 봄 비수기 화요일 | N4: 봄 비수기 수요일 | O4: 봄 비수기 목요일 | P4: 봄 비수기 준주말 | Q4: 봄 비수기 주말 | R4: 봄 비수기 일요일 | S4: 봄 비수기 월요일 | T4: 봄 비수기 화요일 | U4: 봄 비수기 수요일 | V4: 봄 비수기 목요일 | W4: 봄 비수기 준주말 | X4: 봄 비수기 주말 | Y4: 봄 비수기 일요일 | Z4: 봄 비수기 월요일 | AA4: 봄 비수기 화요일 | AB4: 봄 비수기 수요일 | AC4: 봄 비수기 목요일 | AD4: 봄 비수기 준주말 | AE4: 봄 비수기 주말 | AF4: 봄 비수기 일요일 | AG4: 봄 비수기 월요일 | AH4: 봄 비수기 화요일
A5: 설악 쏘라노 | B5: FAM | C5: 디럭스 | D5: 205000 | E5: 119000 | F5: 119000 | G5: 119000 | H5: 119000 | I5: 137000 | J5: 174000 | K5: 119000 | L5: 119000 | M5: 119000 | N5: 119000 | O5: 119000 | P5: 137000 | Q5: 174000 | R5: 119000 | S5: 119000 | T5: 119000 | U5: 119000 | V5: 119000 | W5: 137000 | X5: 174000 | Y5: 119000 | Z5: 119000 | AA5: 119000 | AB5: 119000 | AC5: 119000 | AD5: 137000 | AE5: 174000 | AF5: 119000 | AG5: 119000 | AH5: 119000
A6: 설악 쏘라노 | B6: DMO | C6: 디럭스(모던) | D6: 246000 | E6: 140000 | F6: 140000 | G6: 140000 | H6: 140000 | I6: 174000 | J6: 214000 | K6: 140000 | L6: 140000 | M6: 140000 | N6: 140000 | O6: 140000 | P6: 174000 | Q6: 214000 | R6: 140000 | S6: 140000 | T6: 140000 | U6: 140000 | V6: 140000 | W6: 174000 | X6: 214000 | Y6: 140000 | Z6: 140000 | AA6: 140000 | AB6: 140000 | AC6: 140000 | AD6: 174000 | AE6: 214000 | AF6: 140000 | AG6: 140000 | AH6: 140000
A7: 설악 쏘라노 | B7: FSS | C7: 디럭스(원룸) | D7: 205000 | E7: 119000 | F7: 119000 | G7: 119000 | H7: 119000 | I7: 137000 | J7: 174000 | K7: 119000 | L7: 119000 | M7: 119000 | N7: 119000 | O7: 119000 | P7: 137000 | Q7: 174000 | R7: 119000 | S7: 119000 | T7: 119000 | U7: 119000 | V7: 119000 | W7: 137000 | X7: 174000 | Y7: 119000 | Z7: 119000 | AA7: 119000 | AB7: 119000 | AC7: 119000 | AD7: 137000 | AE7: 174000 | AF7: 119000 | AG7: 119000 | AH7: 119000
A8: 설악 쏘라노 | B8: HTE | C8: 디럭스(유러피언_원룸_호텔형) | D8: 254000 | E8: 147000 | F8: 147000 | G8: 147000 | H8: 147000 | I8: 181000 | J8: 222000 | K8: 147000 | L8: 147000 | M8: 147000 | N8: 147000 | O8: 147000 | P8: 181000 | Q8: 222000 | R8: 147000 | S8: 147000 | T8: 147000 | U8: 147000 | V8: 147000 | W8: 181000 | X8: 222000 | Y8: 147000 | Z8: 147000 | AA8: 147000 | AB8: 147000 | AC8: 147000 | AD8: 181000 | AE8: 222000 | AF8: 147000 | AG8: 147000 | AH8: 147000
A9: 설악 쏘라노 | B9: HTL | C9: 디럭스(원룸_호텔형) | D9: 205000 | E9: 119000 | F9: 119000 | G9: 119000 | H9: 119000 | I9: 137000 | J9: 174000 | K9: 119000 | L9: 119000 | M9: 119000 | N9: 119000 | O9: 119000 | P9: 137000 | Q9: 174000 | R9: 119000 | S9: 119000 | T9: 119000 | U9: 119000 | V9: 119000 | W9: 137000 | X9: 174000 | Y9: 119000 | Z9: 119000 | AA9: 119000 | AB9: 119000 | AC9: 119000 | AD9: 137000 | AE9: 174000 | AF9: 119000 | AG9: 119000 | AH9: 119000
A10: 설악 쏘라노 | B10: FTB | C10: 디럭스(트윈베드) | D10: 205000 | E10: 119000 | F10: 119000 | G10: 119000 | H10: 119000 | I10: 137000 | J10: 174000 | K10: 119000 | L10: 119000 | M10: 119000 | N10: 119000 | O10: 119000 | P10: 137000 | Q10: 174000 | R10: 119000 | S10: 119000 | T10: 119000 | U10: 119000 | V10: 119000 | W10: 137000 | X10: 174000 | Y10: 119000 | Z10: 119000 | AA10: 119000 | AB10: 119000 | AC10: 119000 | AD10: 137000 | AE10: 174000 | AF10: 119000 | AG10: 119000 | AH10: 119000
A11: 설악 쏘라노 | B11: FTL | C11: 디럭스(트윈베드_호텔형) | D11: 205000 | E11: 119000 | F11: 119000 | G11: 119000 | H11: 119000 | I11: 137000 | J11: 174000 | K11: 119000 | L11: 119000 | M11: 119000 | N11: 119000 | O11: 119000 | P11: 137000 | Q11: 174000 | R11: 119000 | S11: 119000 | T11: 119000 | U11: 119000 | V11: 119000 | W11: 137000 | X11: 174000 | Y11: 119000 | Z11: 119000 | AA11: 119000 | AB11: 119000 | AC11: 119000 | AD11: 137000 | AE11: 174000 | AF11: 119000 | AG11: 119000 | AH11: 119000
A12: 설악 쏘라노 | B12: TH1 | C12: 디럭스(티니핑 프린세스룸_호텔형) | D12: 254000 | E12: 140000 | F12: 140000 | G12: 140000 | H12: 140000 | I12: 181000 | J12: 222000 | K12: 140000 | L12: 140000 | M12: 140000 | N12: 140000 | O12: 140000 | P12: 181000 | Q12: 222000 | R12: 140000 | S12: 140000 | T12: 140000 | U12: 140000 | V12: 140000 | W12: 181000 | X12: 222000 | Y12: 140000 | Z12: 140000 | AA12: 140000 | AB12: 140000 | AC12: 140000 | AD12: 181000 | AE12: 222000 | AF12: 140000 | AG12: 140000 | AH12: 140000
A13: 설악 쏘라노 | B13: TH2 | C13: 디럭스(티니핑 연구소룸_호텔형) | D13: 254000 | E13: 140000 | F13: 140000 | G13: 140000 | H13: 140000 | I13: 181000 | J13: 222000 | K13: 140000 | L13: 140000 | M13: 140000 | N13: 140000 | O13: 140000 | P13: 181000 | Q13: 222000 | R13: 140000 | S13: 140000 | T13: 140000 | U13: 140000 | V13: 140000 | W13: 181000 | X13: 222000 | Y13: 140000 | Z13: 140000 | AA13: 140000 | AB13: 140000 | AC13: 140000 | AD13: 181000 | AE13: 222000 | AF13: 140000 | AG13: 140000 | AH13: 140000
A14: 설악 쏘라노 | B14: TH3 | C14: 디럭스(티니핑 슈팅스타룸_호텔형) | D14: 254000 | E14: 140000 | F14: 140000 | G14: 140000 | H14: 140000 | I14: 181000 | J14: 222000 | K14: 140000 | L14: 140000 | M14: 140000 | N14: 140000 | O14: 140000 | P14: 181000 | Q14: 222000 | R14: 140000 | S14: 140000 | T14: 140000 | U14: 140000 | V14: 140000 | W14: 181000 | X14: 222000 | Y14: 140000 | Z14: 140000 | AA14: 140000 | AB14: 140000 | AC14: 140000 | AD14: 181000 | AE14: 222000 | AF14: 140000 | AG14: 140000 | AH14: 140000
A15: 설악 쏘라노 | B15: RYL | C15: 로얄 | D15: 328000 | E15: 190000 | F15: 190000 | G15: 190000 | H15: 190000 | I15: 219000 | J15: 279000 | K15: 190000 | L15: 190000 | M15: 190000 | N15: 190000 | O15: 190000 | P15: 219000 | Q15: 279000 | R15: 190000 | S15: 190000 | T15: 190000 | U15: 190000 | V15: 190000 | W15: 219000 | X15: 279000 | Y15: 190000 | Z15: 190000 | AA15: 190000 | AB15: 190000 | AC15: 190000 | AD15: 219000 | AE15: 279000 | AF15: 190000 | AG15: 190000 | AH15: 190000
A16: 설악 쏘라노 | B16: RMO | C16: 로얄(모던) | D16: 369000 | E16: 211000 | F16: 211000 | G16: 211000 | H16: 211000 | I16: 256000 | J16: 319000 | K16: 211000 | L16: 211000 | M16: 211000 | N16: 211000 | O16: 211000 | P16: 256000 | Q16: 319000 | R16: 211000 | S16: 211000 | T16: 211000 | U16: 211000 | V16: 211000 | W16: 256000 | X16: 319000 | Y16: 211000 | Z16: 211000 | AA16: 211000 | AB16: 211000 | AC16: 211000 | AD16: 256000 | AE16: 319000 | AF16: 211000 | AG16: 211000 | AH16: 211000
... A19: 영업장명 | B19: 객실타입 | C19: 객실명 | D19: 46082 | E19: 46083 | F19: 46084 | G19: 46085 | H19: 46086 | I19: 46087 | J19: 46088 | K19: 46089 | L19: 46090 | M19: 46091 | N19: 46092 | O19: 46093 | P19: 46094 | Q19: 46095 | R19: 46096 | S19: 46097 | T19: 46098 | U19: 46099 | V19: 46100 | W19: 46101 | X19: 46102 | Y19: 46103 | Z19: 46104 | AA19: 46105 | AB19: 46106 | AC19: 46107 | AD19: 46108 | AE19: 46109 | AF19: 46110 | AG19: 46111 | AH19: 46112
D20: =D19 -> 46082 | E20: =E19 -> 46083 | F20: =F19 -> 46084 | G20: =G19 -> 46085 | H20: =H19 -> 46086 | I20: =I19 -> 46087 | J20: =J19 -> 46088 | K20: =K19 -> 46089 | ... AH20: =AH19 -> 46112
D21: 봄 극성수기 연휴 | E21: 봄 비수기 월요일 | F21: 봄 비수기 화요일 | G21: 봄 비수기 수요일 | H21: 봄 비수기 목요일 | I21: 봄 비수기 준주말 | J21: 봄 비수기 주말 | K21: 봄 비수기 일요일 | L21: 봄 비수기 월요일 | M21: 봄 비수기 화요일 | N21: 봄 비수기 수요일 | O21: 봄 비수기 목요일 | P21: 봄 비수기 준주말 | Q21: 봄 비수기 주말 | R21: 봄 비수기 일요일 | S21: 봄 비수기 월요일 | T21: 봄 비수기 화요일 | U21: 봄 비수기 수요일 | V21: 봄 비수기 목요일 | W21: 봄 비수기 준주말 | X21: 봄 비수기 주말 | Y21: 봄 비수기 일요일 | Z21: 봄 비수기 월요일 | AA21: 봄 비수기 화요일 | AB21: 봄 비수기 수요일 | AC21: 봄 비수기 목요일 | AD21: 봄 비수기 준주말 | AE21: 봄 비수기 주말 | AF21: 봄 비수기 일요일 | AG21: 봄 비수기 월요일 | AH21: 봄 비수기 화요일
A22: 설악 별관 | B22: FAM | C22: 디럭스 | D22: 155000 | E22: 87000 | F22: 87000 | G22: 87000 | H22: 87000 | I22: 96000 | J22: 114000 | K22: 87000 | L22: 87000 | M22: 87000 | N22: 87000 | O22: 87000 | P22: 96000 | Q22: 114000 | R22: 87000 | S22: 87000 | T22: 87000 | U22: 87000 | V22: 87000 | W22: 96000 | X22: 114000 | Y22: 87000 | Z22: 87000 | AA22: 87000 | AB22: 87000 | AC22: 87000 | AD22: 96000 | AE22: 114000 | AF22: 87000 | AG22: 87000 | AH22: 87000
A23: 설악 별관 | B23: RYL | C23: 로얄 | D23: 248000 | E23: 138000 | F23: 138000 | G23: 138000 | H23: 138000 | I23: 153000 | J23: 182000 | K23: 138000 | L23: 138000 | M23: 138000 | N23: 138000 | O23: 138000 | P23: 153000 | Q23: 182000 | R23: 138000 | S23: 138000 | T23: 138000 | U23: 138000 | V23: 138000 | W23: 153000 | X23: 182000 | Y23: 138000 | Z23: 138000 | AA23: 138000 | AB23: 138000 | AC23: 138000 | AD23: 153000 | AE23: 182000 | AF23: 138000 | AG23: 138000 | AH23: 138000
A24: 영업장명 | B24: 객실타입 | C24: 객실명 | D24: 46082 | E24: 46083 | F24: 46084 | G24: 46085 | H24: 46086 | I24: 46087 | J24: 46088 | K24: 46089 | L24: 46090 | M24: 46091 | N24: 46092 | O24: 46093 | P24: 46094 | Q24: 46095 | R24: 46096 | S24: 46097 | T24: 46098 | U24: 46099 | V24: 46100 | W24: 46101 | X24: 46102 | Y24: 46103 | Z24: 46104 | AA24: 46105 | AB24: 46106 | AC24: 46107 | AD24: 46108 | AE24: 46109 | AF24: 46110 | AG24: 46111 | AH24: 46112
D25: =D24 -> 46082 | E25: =E24 -> 46083 | F25: =F24 -> 46084 | G25: =G24 -> 46085 | H25: =H24 -> 46086 | I25: =I24 -> 46087 | J25: =J24 -> 46088 | K25: =K24 -> 46089 | ... AH25: =AH24 -> 46112
D26: 봄 극성수기 연휴 | E26: 봄 비수기 월요일 | F26: 봄 비수기 화요일 | G26: 봄 비수기 수요일 | H26: 봄 비수기 목요일 | I26: 봄 비수기 준주말 | J26: 봄 비수기 주말 | K26: 봄 비수기 일요일 | L26: 봄 비수기 월요일 | M26: 봄 비수기 화요일 | N26: 봄 비수기 수요일 | O26: 봄 비수기 목요일 | P26: 봄 비수기 준주말 | Q26: 봄 비수기 주말 | R26: 봄 비수기 일요일 | S26: 봄 비수기 월요일 | T26: 봄 비수기 화요일 | U26: 봄 비수기 수요일 | V26: 봄 비수기 목요일 | W26: 봄 비수기 준주말 | X26: 봄 비수기 주말 | Y26: 봄 비수기 일요일 | Z26: 봄 비수기 월요일 | AA26: 봄 비수기 화요일 | AB26: 봄 비수기 수요일 | AC26: 봄 비수기 목요일 | AD26: 봄 비수기 준주말 | AE26: 봄 비수기 주말 | AF26: 봄 비수기 일요일 | AG26: 봄 비수기 월요일 | AH26: 봄 비수기 화요일
A27: 용인 베잔송 | B27: FAM | C27: 디럭스 | D27: 192000 | E27: 112000 | F27: 112000 | G27: 112000 | H27: 112000 | I27: 134000 | J27: 164000 | K27: 112000 | L27: 112000 | M27: 112000 | N27: 112000 | O27: 112000 | P27: 134000 | Q27: 164000 | R27: 112000 | S27: 112000 | T27: 112000 | U27: 112000 | V27: 112000 | W27: 134000 | X27: 164000 | Y27: 112000 | Z27: 112000 | AA27: 112000 | AB27: 112000 | AC27: 112000 | AD27: 134000 | AE27: 164000 | AF27: 112000 | AG27: 112000 | AH27: 112000
A28: 용인 베잔송 | B28: HTL | C28: 디럭스(호텔형) | D28: 192000 | E28: 112000 | F28: 112000 | G28: 112000 | H28: 112000 | I28: 134000 | J28: 164000 | K28: 112000 | L28: 112000 | M28: 112000 | N28: 112000 | O28: 112000 | P28: 134000 | Q28: 164000 | R28: 112000 | S28: 112000 | T28: 112000 | U28: 112000 | V28: 112000 | W28: 134000 | X28: 164000 | Y28: 112000 | Z28: 112000 | AA28: 112000 | AB28: 112000 | AC28: 112000 | AD28: 134000 | AE28: 164000 | AF28: 112000 | AG28: 112000 | AH28: 112000
A29: 용인 베잔송 | B29: FST | C29: 디럭스(싱글트윈) | D29: 192000 | E29: 112000 | F29: 112000 | G29: 112000 | H29: 112000 | I29: 134000 | J29: 164000 | K29: 112000 | L29: 112000 | M29: 112000 | N29: 112000 | O29: 112000 | P29: 134000 | Q29: 164000 | R29: 112000 | S29: 112000 | T29: 112000 | U29: 112000 | V29: 112000 | W29: 134000 | X29: 164000 | Y29: 112000 | Z29: 112000 | AA29: 112000 | AB29: 112000 | AC29: 112000 | AD29: 134000 | AE29: 164000 | AF29: 112000 | AG29: 112000 | AH29: 112000
A30: 용인 베잔송 | B30: TH1 | C30: 디럭스(티니핑 프린세스룸_호텔형) | D30: 240000 | E30: 133000 | F30: 133000 | G30: 133000 | H30: 133000 | I30: 179000 | J30: 212000 | K30: 133000 | L30: 133000 | M30: 133000 | N30: 133000 | O30: 133000 | P30: 179000 | Q30: 212000 | R30: 133000 | S30: 133000 | T30: 133000 | U30: 133000 | V30: 133000 | W30: 179000 | X30: 212000 | Y30: 133000 | Z30: 133000 | AA30: 133000 | AB30: 133000 | AC30: 133000 | AD30: 179000 | AE30: 212000 | AF30: 133000 | AG30: 133000 | AH30: 133000
A31: 용인 베잔송 | B31: TH2 | C31: 디럭스(티니핑 연구소룸_호텔형) | D31: 240000 | E31: 133000 | F31: 133000 | G31: 133000 | H31: 133000 | I31: 179000 | J31: 212000 | K31: 133000 | L31: 133000 | M31: 133000 | N31: 133000 | O31: 133000 | P31: 179000 | Q31: 212000 | R31: 133000 | S31: 133000 | T31: 133000 | U31: 133000 | V31: 133000 | W31: 179000 | X31: 212000 | Y31: 133000 | Z31: 133000 | AA31: 133000 | AB31: 133000 | AC31: 133000 | AD31: 179000 | AE31: 212000 | AF31: 133000 | AG31: 133000 | AH31: 133000
A32: 용인 베잔송 | B32: TH3 | C32: 디럭스(티니핑 슈팅스타룸_호텔형) | D32: 240000 | E32: 133000 | F32: 133000 | G32: 133000 | H32: 133000 | I32: 179000 | J32: 212000 | K32: 133000 | L32: 133000 | M32: 133000 | N32: 133000 | O32: 133000 | P32: 179000 | Q32: 212000 | R32: 133000 | S32: 133000 | T32: 133000 | U32: 133000 | V32: 133000 | W32: 179000 | X32: 212000 | Y32: 133000 | Z32: 133000 | AA32: 133000 | AB32: 133000 | AC32: 133000 | AD32: 179000 | AE32: 212000 | AF32: 133000 | AG32: 133000 | AH32: 133000
A33: 용인 베잔송 | B33: RYL | C33: 로얄 | D33: 307000 | E33: 180000 | F33: 180000 | G33: 180000 | H33: 180000 | I33: 215000 | J33: 263000 | K33: 180000 | L33: 180000 | M33: 180000 | N33: 180000 | O33: 180000 | P33: 215000 | Q33: 263000 | R33: 180000 | S33: 180000 | T33: 180000 | U33: 180000 | V33: 180000 | W33: 215000 | X33: 263000 | Y33: 180000 | Z33: 180000 | AA33: 180000 | AB33: 180000 | AC33: 180000 | AD33: 215000 | AE33: 263000 | AF33: 180000 | AG33: 180000 | AH33: 180000
A34: 영업장명 | B34: 객실타입 | C34: 객실명 | D34: 46082 | E34: 46083 | F34: 46084 | G34: 46085 | H34: 46086 | I34: 46087 | J34: 46088 | K34: 46089 | L34: 46090 | M34: 46091 | N34: 46092 | O34: 46093 | P34: 46094 | Q34: 46095 | R34: 46096 | S34: 46097 | T34: 46098 | U34: 46099 | V34: 46100 | W34: 46101 | X34: 46102 | Y34: 46103 | Z34: 46104 | AA34: 46105 | AB34: 46106 | AC34: 46107 | AD34: 46108 | AE34: 46109 | AF34: 46110 | AG34: 46111 | AH34: 46112
D35: =D34 -> 46082 | E35: =E34 -> 46083 | F35: =F34 -> 46084 | G35: =G34 -> 46085 | H35: =H34 -> 46086 | I35: =I34 -> 46087 | J35: =J34 -> 46088 | K35: =K34 -> 46089 | ... AH35: =AH34 -> 46112
D36: 봄 극성수기 연휴 | E36: 봄 비수기 월요일 | F36: 봄 비수기 화요일 | G36: 봄 비수기 수요일 | H36: 봄 비수기 목요일 | I36: 봄 비수기 준주말 | J36: 봄 비수기 주말 | K36: 봄 비수기 일요일 | L36: 봄 비수기 월요일 | M36: 봄 비수기 화요일 | N36: 봄 비수기 수요일 | O36: 봄 비수기 목요일 | P36: 봄 비수기 준주말 | Q36: 봄 비수기 주말 | R36: 봄 비수기 일요일 | S36: 봄 비수기 월요일 | T36: 봄 비수기 화요일 | U36: 봄 비수기 수요일 | V36: 봄 비수기 목요일 | W36: 봄 비수기 준주말 | X36: 봄 비수기 주말 | Y36: 봄 비수기 일요일 | Z36: 봄 비수기 월요일 | AA36: 봄 비수기 화요일 | AB36: 봄 비수기 수요일 | AC36: 봄 비수기 목요일 | AD36: 봄 비수기 준주말 | AE36: 봄 비수기 주말 | AF36: 봄 비수기 일요일 | AG36: 봄 비수기 월요일 | AH36: 봄 비수기 화요일
A37: 산정호수 안시 | B37: FAM | C37: 디럭스 | D37: 200000 | E37: 118000 | F37: 118000 | G37: 118000 | H37: 118000 | I37: 141000 | J37: 175000 | K37: 118000 | L37: 118000 | M37: 118000 | N37: 118000 | O37: 118000 | P37: 141000 | Q37: 175000 | R37: 118000 | S37: 118000 | T37: 118000 | U37: 118000 | V37: 118000 | W37: 141000 | X37: 175000 | Y37: 118000 | Z37: 118000 | AA37: 118000 | AB37: 118000 | AC37: 118000 | AD37: 141000 | AE37: 175000 | AF37: 118000 | AG37: 118000 | AH37: 118000
A38: 산정호수 안시 | B38: HTL | C38: 디럭스(호텔형) | D38: 200000 | E38: 118000 | F38: 118000 | G38: 118000 | H38: 118000 | I38: 141000 | J38: 175000 | K38: 118000 | L38: 118000 | M38: 118000 | N38: 118000 | O38: 118000 | P38: 141000 | Q38: 175000 | R38: 118000 | S38: 118000 | T38: 118000 | U38: 118000 | V38: 118000 | W38: 141000 | X38: 175000 | Y38: 118000 | Z38: 118000 | AA38: 118000 | AB38: 118000 | AC38: 118000 | AD38: 141000 | AE38: 175000 | AF38: 118000 | AG38: 118000 | AH38: 118000
A39: 산정호수 안시 | B39: FST | C39: 디럭스(싱글트윈) | D39: 200000 | E39: 118000 | F39: 118000 | G39: 118000 | H39: 118000 | I39: 141000 | J39: 175000 | K39: 118000 | L39: 118000 | M39: 118000 | N39: 118000 | O39: 118000 | P39: 141000 | Q39: 175000 | R39: 118000 | S39: 118000 | T39: 118000 | U39: 118000 | V39: 118000 | W39: 141000 | X39: 175000 | Y39: 118000 | Z39: 118000 | AA39: 118000 | AB39: 118000 | AC39: 118000 | AD39: 141000 | AE39: 175000 | AF39: 118000 | AG39: 118000 | AH39: 118000
A40: 산정호수 안시 | B40: RYL | C40: 로얄 | D40: 319000 | E40: 189000 | F40: 189000 | G40: 189000 | H40: 189000 | I40: 225000 | J40: 280000 | K40: 189000 | L40: 189000 | M40: 189000 | N40: 189000 | O40: 189000 | P40: 225000 | Q40: 280000 | R40: 189000 | S40: 189000 | T40: 189000 | U40: 189000 | V40: 189000 | W40: 225000 | X40: 280000 | Y40: 189000 | Z40: 189000 | AA40: 189000 | AB40: 189000 | AC40: 189000 | AD40: 225000 | AE40: 280000 | AF40: 189000 | AG40: 189000 | AH40: 189000
A41: 영업장명 | B41: 객실타입 | C41: 객실명 | D41: 46082 | E41: 46083 | F41: 46084 | G41: 46085 | H41: 46086 | I41: 46087 | J41: 46088 | K41: 46089 | L41: 46090 | M41: 46091 | N41: 46092 | O41: 46093 | P41: 46094 | Q41: 46095 | R41: 46096 | S41: 46097 | T41: 46098 | U41: 46099 | V41: 46100 | W41: 46101 | X41: 46102 | Y41: 46103 | Z41: 46104 | AA41: 46105 | AB41: 46106 | AC41: 46107 | AD41: 46108 | AE41: 46109 | AF41: 46110 | AG41: 46111 | AH41: 46112
D42: =D41 -> 46082 | E42: =E41 -> 46083 | F42: =F41 -> 46084 | G42: =G41 -> 46085 | H42: =H41 -> 46086 | I42: =I41 -> 46087 | J42: =J41 -> 46088 | K42: =K41 -> 46089 | ... AH42: =AH41 -> 46112
...

Sheet 4월(무기명)
A1: ■ 2026년 4월 - 무기명
A2: 영업장명 | B2: 객실타입 | C2: 객실명 | D2: 46113 | E2: 46114 | F2: 46115 | G2: 46116 | H2: 46117 | I2: 46118 | J2: 46119 | K2: 46120 | L2: 46121 | M2: 46122 | N2: 46123 | O2: 46124 | P2: 46125 | Q2: 46126 | R2: 46127 | S2: 46128 | T2: 46129 | U2: 46130 | V2: 46131 | W2: 46132 | X2: 46133 | Y2: 46134 | Z2: 46135 | AA2: 46136 | AB2: 46137 | AC2: 46138 | AD2: 46139 | AE2: 46140 | AF2: 46141 | AG2: 46142
D3: =D2 -> 46113 | E3: =E2 -> 46114 | F3: =F2 -> 46115 | G3: =G2 -> 46116 | H3: =H2 -> 46117 | I3: =I2 -> 46118 | J3: =J2 -> 46119 | K3: =K2 -> 46120 | ... AG3: =AG2 -> 46142
D4: 봄 비수기 수요일 | E4: 봄 비수기 목요일 | F4: 봄 비수기 준주말 | G4: 봄 비수기 주말 | H4: 봄 비수기 일요일 | I4: 봄 비수기 월요일 | J4: 봄 비수기 화요일 | K4: 봄 비수기 수요일 | L4: 봄 비수기 목요일 | M4: 봄 비수기 준주말 | N4: 봄 비수기 주말 | O4: 봄 비수기 일요일 | P4: 봄 비수기 월요일 | Q4: 봄 비수기 화요일 | R4: 봄 비수기 수요일 | S4: 봄 비수기 목요일 | T4: 봄 비수기 준주말 | U4: 봄 비수기 주말 | V4: 봄 비수기 일요일 | W4: 봄 비수기 월요일 | X4: 봄 비수기 화요일 | Y4: 봄 비수기 수요일 | Z4: 봄 비수기 목요일 | AA4: 봄 비수기 준주말 | AB4: 봄 비수기 주말 | AC4: 봄 비수기 일요일 | AD4: 봄 비수기 월요일 | AE4: 봄 비수기 화요일 | AF4: 봄 비수기 수요일 | AG4: 봄 비수기 목요일
A5: 설악 쏘라노 | B5: FAM | C5: 디럭스 | D5: 139000 | E5: 139000 | F5: 159000 | G5: 196000 | H5: 139000 | I5: 139000 | J5: 139000 | K5: 139000 | L5: 139000 | M5: 159000 | N5: 196000 | O5: 139000 | P5: 139000 | Q5: 139000 | R5: 139000 | S5: 139000 | T5: 159000 | U5: 196000 | V5: 139000 | W5: 139000 | X5: 139000 | Y5: 139000 | Z5: 139000 | AA5: 159000 | AB5: 196000 | AC5: 139000 | AD5: 139000 | AE5: 139000 | AF5: 139000 | AG5: 139000
A6: 설악 쏘라노 | B6: DMO | C6: 디럭스(모던) | D6: 169000 | E6: 169000 | F6: 209000 | G6: 246000 | H6: 169000 | I6: 169000 | J6: 169000 | K6: 169000 | L6: 169000 | M6: 209000 | N6: 246000 | O6: 169000 | P6: 169000 | Q6: 169000 | R6: 169000 | S6: 169000 | T6: 209000 | U6: 246000 | V6: 169000 | W6: 169000 | X6: 169000 | Y6: 169000 | Z6: 169000 | AA6: 209000 | AB6: 246000 | AC6: 169000 | AD6: 169000 | AE6: 169000 | AF6: 169000 | AG6: 169000
A7: 설악 쏘라노 | B7: FSS | C7: 디럭스(원룸) | D7: 139000 | E7: 139000 | F7: 159000 | G7: 196000 | H7: 139000 | I7: 139000 | J7: 139000 | K7: 139000 | L7: 139000 | M7: 159000 | N7: 196000 | O7: 139000 | P7: 139000 | Q7: 139000 | R7: 139000 | S7: 139000 | T7: 159000 | U7: 196000 | V7: 139000 | W7: 139000 | X7: 139000 | Y7: 139000 | Z7: 139000 | AA7: 159000 | AB7: 196000 | AC7: 139000 | AD7: 139000 | AE7: 139000 | AF7: 139000 | AG7: 139000
A8: 설악 쏘라노 | B8: HTE | C8: 디럭스(유러피언_원룸_호텔형) | D8: 179000 | E8: 179000 | F8: 219000 | G8: 256000 | H8: 179000 | I8: 179000 | J8: 179000 | K8: 179000 | L8: 179000 | M8: 219000 | N8: 256000 | O8: 179000 | P8: 179000 | Q8: 179000 | R8: 179000 | S8: 179000 | T8: 219000 | U8: 256000 | V8: 179000 | W8: 179000 | X8: 179000 | Y8: 179000 | Z8: 179000 | AA8: 219000 | AB8: 256000 | AC8: 179000 | AD8: 179000 | AE8: 179000 | AF8: 179000 | AG8: 179000
A9: 설악 쏘라노 | B9: HTL | C9: 디럭스(원룸_호텔형) | D9: 139000 | E9: 139000 | F9: 159000 | G9: 196000 | H9: 139000 | I9: 139000 | J9: 139000 | K9: 139000 | L9: 139000 | M9: 159000 | N9: 196000 | O9: 139000 | P9: 139000 | Q9: 139000 | R9: 139000 | S9: 139000 | T9: 159000 | U9: 196000 | V9: 139000 | W9: 139000 | X9: 139000 | Y9: 139000 | Z9: 139000 | AA9: 159000 | AB9: 196000 | AC9: 139000 | AD9: 139000 | AE9: 139000 | AF9: 139000 | AG9: 139000
A10: 설악 쏘라노 | B10: FTB | C10: 디럭스(트윈베드) | D10: 139000 | E10: 139000 | F10: 159000 | G10: 196000 | H10: 139000 | I10: 139000 | J10: 139000 | K10: 139000 | L10: 139000 | M10: 159000 | N10: 196000 | O10: 139000 | P10: 139000 | Q10: 139000 | R10: 139000 | S10: 139000 | T10: 159000 | U10: 196000 | V10: 139000 | W10: 139000 | X10: 139000 | Y10: 139000 | Z10: 139000 | AA10: 159000 | AB10: 196000 | AC10: 139000 | AD10: 139000 | AE10: 139000 | AF10: 139000 | AG10: 139000
A11: 설악 쏘라노 | B11: FTL | C11: 디럭스(트윈베드_호텔형) | D11: 139000 | E11: 139000 | F11: 159000 | G11: 196000 | H11: 139000 | I11: 139000 | J11: 139000 | K11: 139000 | L11: 139000 | M11: 159000 | N11: 196000 | O11: 139000 | P11: 139000 | Q11: 139000 | R11: 139000 | S11: 139000 | T11: 159000 | U11: 196000 | V11: 139000 | W11: 139000 | X11: 139000 | Y11: 139000 | Z11: 139000 | AA11: 159000 | AB11: 196000 | AC11: 139000 | AD11: 139000 | AE11: 139000 | AF11: 139000 | AG11: 139000
A12: 설악 쏘라노 | B12: TH1 | C12: 디럭스(티니핑 프린세스룸_호텔형) | D12: 169000 | E12: 169000 | F12: 219000 | G12: 256000 | H12: 169000 | I12: 169000 | J12: 169000 | K12: 169000 | L12: 169000 | M12: 219000 | N12: 256000 | O12: 169000 | P12: 169000 | Q12: 169000 | R12: 169000 | S12: 169000 | T12: 219000 | U12: 256000 | V12: 169000 | W12: 169000 | X12: 169000 | Y12: 169000 | Z12: 169000 | AA12: 219000 | AB12: 256000 | AC12: 169000 | AD12: 169000 | AE12: 169000 | AF12: 169000 | AG12: 169000
A13: 설악 쏘라노 | B13: TH2 | C13: 디럭스(티니핑 연구소룸_호텔형) | D13: 169000 | E13: 169000 | F13: 219000 | G13: 256000 | H13: 169000 | I13: 169000 | J13: 169000 | K13: 169000 | L13: 169000 | M13: 219000 | N13: 256000 | O13: 169000 | P13: 169000 | Q13: 169000 | R13: 169000 | S13: 169000 | T13: 219000 | U13: 256000 | V13: 169000 | W13: 169000 | X13: 169000 | Y13: 169000 | Z13: 169000 | AA13: 219000 | AB13: 256000 | AC13: 169000 | AD13: 169000 | AE13: 169000 | AF13: 169000 | AG13: 169000
A14: 설악 쏘라노 | B14: TH3 | C14: 디럭스(티니핑 슈팅스타룸_호텔형) | D14: 169000 | E14: 169000 | F14: 219000 | G14: 256000 | H14: 169000 | I14: 169000 | J14: 169000 | K14: 169000 | L14: 169000 | M14: 219000 | N14: 256000 | O14: 169000 | P14: 169000 | Q14: 169000 | R14: 169000 | S14: 169000 | T14: 219000 | U14: 256000 | V14: 169000 | W14: 169000 | X14: 169000 | Y14: 169000 | Z14: 169000 | AA14: 219000 | AB14: 256000 | AC14: 169000 | AD14: 169000 | AE14: 169000 | AF14: 169000 | AG14: 169000
A15: 설악 쏘라노 | B15: RYL | C15: 로얄 | D15: 223000 | E15: 223000 | F15: 254000 | G15: 314000 | H15: 223000 | I15: 223000 | J15: 223000 | K15: 223000 | L15: 223000 | M15: 254000 | N15: 314000 | O15: 223000 | P15: 223000 | Q15: 223000 | R15: 223000 | S15: 223000 | T15: 254000 | U15: 314000 | V15: 223000 | W15: 223000 | X15: 223000 | Y15: 223000 | Z15: 223000 | AA15: 254000 | AB15: 314000 | AC15: 223000 | AD15: 223000 | AE15: 223000 | AF15: 223000 | AG15: 223000
A16: 설악 쏘라노 | B16: RMO | C16: 로얄(모던) | D16: 253000 | E16: 253000 | F16: 304000 | G16: 364000 | H16: 253000 | I16: 253000 | J16: 253000 | K16: 253000 | L16: 253000 | M16: 304000 | N16: 364000 | O16: 253000 | P16: 253000 | Q16: 253000 | R16: 253000 | S16: 253000 | T16: 304000 | U16: 364000 | V16: 253000 | W16: 253000 | X16: 253000 | Y16: 253000 | Z16: 253000 | AA16: 304000 | AB16: 364000 | AC16: 253000 | AD16: 253000 | AE16: 253000 | AF16: 253000 | AG16: 253000
... A19: 영업장명 | B19: 객실타입 | C19: 객실명 | D19: 46113 | E19: 46114 | F19: 46115 | G19: 46116 | H19: 46117 | I19: 46118 | J19: 46119 | K19: 46120 | L19: 46121 | M19: 46122 | N19: 46123 | O19: 46124 | P19: 46125 | Q19: 46126 | R19: 46127 | S19: 46128 | T19: 46129 | U19: 46130 | V19: 46131 | W19: 46132 | X19: 46133 | Y19: 46134 | Z19: 46135 | AA19: 46136 | AB19: 46137 | AC19: 46138 | AD19: 46139 | AE19: 46140 | AF19: 46141 | AG19: 46142
D20: =D19 -> 46113 | E20: =E19 -> 46114 | F20: =F19 -> 46115 | G20: =G19 -> 46116 | H20: =H19 -> 46117 | I20: =I19 -> 46118 | J20: =J19 -> 46119 | K20: =K19 -> 46120 | ... AG20: =AG19 -> 46142
D21: 봄 비수기 수요일 | E21: 봄 비수기 목요일 | F21: 봄 비수기 준주말 | G21: 봄 비수기 주말 | H21: 봄 비수기 일요일 | I21: 봄 비수기 월요일 | J21: 봄 비수기 화요일 | K21: 봄 비수기 수요일 | L21: 봄 비수기 목요일 | M21: 봄 비수기 준주말 | N21: 봄 비수기 주말 | O21: 봄 비수기 일요일 | P21: 봄 비수기 월요일 | Q21: 봄 비수기 화요일 | R21: 봄 비수기 수요일 | S21: 봄 비수기 목요일 | T21: 봄 비수기 준주말 | U21: 봄 비수기 주말 | V21: 봄 비수기 일요일 | W21: 봄 비수기 월요일 | X21: 봄 비수기 화요일 | Y21: 봄 비수기 수요일 | Z21: 봄 비수기 목요일 | AA21: 봄 비수기 준주말 | AB21: 봄 비수기 주말 | AC21: 봄 비수기 일요일 | AD21: 봄 비수기 월요일 | AE21: 봄 비수기 화요일 | AF21: 봄 비수기 수요일 | AG21: 봄 비수기 목요일
A22: 설악 별관 | B22: FAM | C22: 디럭스 | D22: 123000 | E22: 123000 | F22: 136000 | G22: 162000 | H22: 123000 | I22: 123000 | J22: 123000 | K22: 123000 | L22: 123000 | M22: 136000 | N22: 162000 | O22: 123000 | P22: 123000 | Q22: 123000 | R22: 123000 | S22: 123000 | T22: 136000 | U22: 162000 | V22: 123000 | W22: 123000 | X22: 123000 | Y22: 123000 | Z22: 123000 | AA22: 136000 | AB22: 162000 | AC22: 123000 | AD22: 123000 | AE22: 123000 | AF22: 123000 | AG22: 123000
A23: 설악 별관 | B23: RYL | C23: 로얄 | D23: 197000 | E23: 197000 | F23: 218000 | G23: 260000 | H23: 197000 | I23: 197000 | J23: 197000 | K23: 197000 | L23: 197000 | M23: 218000 | N23: 260000 | O23: 197000 | P23: 197000 | Q23: 197000 | R23: 197000 | S23: 197000 | T23: 218000 | U23: 260000 | V23: 197000 | W23: 197000 | X23: 197000 | Y23: 197000 | Z23: 197000 | AA23: 218000 | AB23: 260000 | AC23: 197000 | AD23: 197000 | AE23: 197000 | AF23: 197000 | AG23: 197000
A24: 영업장명 | B24: 객실타입 | C24: 객실명 | D24: 46113 | E24: 46114 | F24: 46115 | G24: 46116 | H24: 46117 | I24: 46118 | J24: 46119 | K24: 46120 | L24: 46121 | M24: 46122 | N24: 46123 | O24: 46124 | P24: 46125 | Q24: 46126 | R24: 46127 | S24: 46128 | T24: 46129 | U24: 46130 | V24: 46131 | W24: 46132 | X24: 46133 | Y24: 46134 | Z24: 46135 | AA24: 46136 | AB24: 46137 | AC24: 46138 | AD24: 46139 | AE24: 46140 | AF24: 46141 | AG24: 46142
D25: =D24 -> 46113 | E25: =E24 -> 46114 | F25: =F24 -> 46115 | G25: =G24 -> 46116 | H25: =H24 -> 46117 | I25: =I24 -> 46118 | J25: =J24 -> 46119 | K25: =K24 -> 46120 | ... AG25: =AG24 -> 46142
D26: 봄 비수기 수요일 | E26: 봄 비수기 목요일 | F26: 봄 비수기 준주말 | G26: 봄 비수기 주말 | H26: 봄 비수기 일요일 | I26: 봄 비수기 월요일 | J26: 봄 비수기 화요일 | K26: 봄 비수기 수요일 | L26: 봄 비수기 목요일 | M26: 봄 비수기 준주말 | N26: 봄 비수기 주말 | O26: 봄 비수기 일요일 | P26: 봄 비수기 월요일 | Q26: 봄 비수기 화요일 | R26: 봄 비수기 수요일 | S26: 봄 비수기 목요일 | T26: 봄 비수기 준주말 | U26: 봄 비수기 주말 | V26: 봄 비수기 일요일 | W26: 봄 비수기 월요일 | X26: 봄 비수기 화요일 | Y26: 봄 비수기 수요일 | Z26: 봄 비수기 목요일 | AA26: 봄 비수기 준주말 | AB26: 봄 비수기 주말 | AC26: 봄 비수기 일요일 | AD26: 봄 비수기 월요일 | AE26: 봄 비수기 화요일 | AF26: 봄 비수기 수요일 | AG26: 봄 비수기 목요일
A27: 용인 베잔송 | B27: FAM | C27: 디럭스 | D27: 128000 | E27: 128000 | F27: 142000 | G27: 177000 | H27: 128000 | I27: 128000 | J27: 128000 | K27: 128000 | L27: 128000 | M27: 142000 | N27: 177000 | O27: 128000 | P27: 128000 | Q27: 128000 | R27: 128000 | S27: 128000 | T27: 142000 | U27: 177000 | V27: 128000 | W27: 128000 | X27: 128000 | Y27: 128000 | Z27: 128000 | AA27: 142000 | AB27: 177000 | AC27: 128000 | AD27: 128000 | AE27: 128000 | AF27: 128000 | AG27: 128000
A28: 용인 베잔송 | B28: HTL | C28: 디럭스(호텔형) | D28: 128000 | E28: 128000 | F28: 142000 | G28: 177000 | H28: 128000 | I28: 128000 | J28: 128000 | K28: 128000 | L28: 128000 | M28: 142000 | N28: 177000 | O28: 128000 | P28: 128000 | Q28: 128000 | R28: 128000 | S28: 128000 | T28: 142000 | U28: 177000 | V28: 128000 | W28: 128000 | X28: 128000 | Y28: 128000 | Z28: 128000 | AA28: 142000 | AB28: 177000 | AC28: 128000 | AD28: 128000 | AE28: 128000 | AF28: 128000 | AG28: 128000
A29: 용인 베잔송 | B29: FST | C29: 디럭스(싱글트윈) | D29: 128000 | E29: 128000 | F29: 142000 | G29: 177000 | H29: 128000 | I29: 128000 | J29: 128000 | K29: 128000 | L29: 128000 | M29: 142000 | N29: 177000 | O29: 128000 | P29: 128000 | Q29: 128000 | R29: 128000 | S29: 128000 | T29: 142000 | U29: 177000 | V29: 128000 | W29: 128000 | X29: 128000 | Y29: 128000 | Z29: 128000 | AA29: 142000 | AB29: 177000 | AC29: 128000 | AD29: 128000 | AE29: 128000 | AF29: 128000 | AG29: 128000
A30: 용인 베잔송 | B30: TH1 | C30: 디럭스(티니핑 프린세스룸_호텔형) | D30: 158000 | E30: 158000 | F30: 202000 | G30: 237000 | H30: 158000 | I30: 158000 | J30: 158000 | K30: 158000 | L30: 158000 | M30: 202000 | N30: 237000 | O30: 158000 | P30: 158000 | Q30: 158000 | R30: 158000 | S30: 158000 | T30: 202000 | U30: 237000 | V30: 158000 | W30: 158000 | X30: 158000 | Y30: 158000 | Z30: 158000 | AA30: 202000 | AB30: 237000 | AC30: 158000 | AD30: 158000 | AE30: 158000 | AF30: 158000 | AG30: 158000
A31: 용인 베잔송 | B31: TH2 | C31: 디럭스(티니핑 연구소룸_호텔형) | D31: 158000 | E31: 158000 | F31: 202000 | G31: 237000 | H31: 158000 | I31: 158000 | J31: 158000 | K31: 158000 | L31: 158000 | M31: 202000 | N31: 237000 | O31: 158000 | P31: 158000 | Q31: 158000 | R31: 158000 | S31: 158000 | T31: 202000 | U31: 237000 | V31: 158000 | W31: 158000 | X31: 158000 | Y31: 158000 | Z31: 158000 | AA31: 202000 | AB31: 237000 | AC31: 158000 | AD31: 158000 | AE31: 158000 | AF31: 158000 | AG31: 158000
A32: 용인 베잔송 | B32: TH3 | C32: 디럭스(티니핑 슈팅스타룸_호텔형) | D32: 158000 | E32: 158000 | F32: 202000 | G32: 237000 | H32: 158000 | I32: 158000 | J32: 158000 | K32: 158000 | L32: 158000 | M32: 202000 | N32: 237000 | O32: 158000 | P32: 158000 | Q32: 158000 | R32: 158000 | S32: 158000 | T32: 202000 | U32: 237000 | V32: 158000 | W32: 158000 | X32: 158000 | Y32: 158000 | Z32: 158000 | AA32: 202000 | AB32: 237000 | AC32: 158000 | AD32: 158000 | AE32: 158000 | AF32: 158000 | AG32: 158000
A33: 용인 베잔송 | B33: RYL | C33: 로얄 | D33: 205000 | E33: 205000 | F33: 227000 | G33: 283000 | H33: 205000 | I33: 205000 | J33: 205000 | K33: 205000 | L33: 205000 | M33: 227000 | N33: 283000 | O33: 205000 | P33: 205000 | Q33: 205000 | R33: 205000 | S33: 205000 | T33: 227000 | U33: 283000 | V33: 205000 | W33: 205000 | X33: 205000 | Y33: 205000 | Z33: 205000 | AA33: 227000 | AB33: 283000 | AC33: 205000 | AD33: 205000 | AE33: 205000 | AF33: 205000 | AG33: 205000
A34: 영업장명 | B34: 객실타입 | C34: 객실명 | D34: 46113 | E34: 46114 | F34: 46115 | G34: 46116 | H34: 46117 | I34: 46118 | J34: 46119 | K34: 46120 | L34: 46121 | M34: 46122 | N34: 46123 | O34: 46124 | P34: 46125 | Q34: 46126 | R34: 46127 | S34: 46128 | T34: 46129 | U34: 46130 | V34: 46131 | W34: 46132 | X34: 46133 | Y34: 46134 | Z34: 46135 | AA34: 46136 | AB34: 46137 | AC34: 46138 | AD34: 46139 | AE34: 46140 | AF34: 46141 | AG34: 46142
D35: =D34 -> 46113 | E35: =E34 -> 46114 | F35: =F34 -> 46115 | G35: =G34 -> 46116 | H35: =H34 -> 46117 | I35: =I34 -> 46118 | J35: =J34 -> 46119 | K35: =K34 -> 46120 | ... AG35: =AG34 -> 46142
D36: 봄 비수기 수요일 | E36: 봄 비수기 목요일 | F36: 봄 비수기 준주말 | G36: 봄 비수기 주말 | H36: 봄 비수기 일요일 | I36: 봄 비수기 월요일 | J36: 봄 비수기 화요일 | K36: 봄 비수기 수요일 | L36: 봄 비수기 목요일 | M36: 봄 비수기 준주말 | N36: 봄 비수기 주말 | O36: 봄 비수기 일요일 | P36: 봄 비수기 월요일 | Q36: 봄 비수기 화요일 | R36: 봄 비수기 수요일 | S36: 봄 비수기 목요일 | T36: 봄 비수기 준주말 | U36: 봄 비수기 주말 | V36: 봄 비수기 일요일 | W36: 봄 비수기 월요일 | X36: 봄 비수기 화요일 | Y36: 봄 비수기 수요일 | Z36: 봄 비수기 목요일 | AA36: 봄 비수기 준주말 | AB36: 봄 비수기 주말 | AC36: 봄 비수기 일요일 | AD36: 봄 비수기 월요일 | AE36: 봄 비수기 화요일 | AF36: 봄 비수기 수요일 | AG36: 봄 비수기 목요일
A37: 산정호수 안시 | B37: FAM | C37: 디럭스 | D37: 132000 | E37: 132000 | F37: 141000 | G37: 197000 | H37: 132000 | I37: 132000 | J37: 132000 | K37: 132000 | L37: 132000 | M37: 141000 | N37: 197000 | O37: 132000 | P37: 132000 | Q37: 132000 | R37: 132000 | S37: 132000 | T37: 141000 | U37: 197000 | V37: 132000 | W37: 132000 | X37: 132000 | Y37: 132000 | Z37: 132000 | AA37: 141000 | AB37: 197000 | AC37: 132000 | AD37: 132000 | AE37: 132000 | AF37: 132000 | AG37: 132000
A38: 산정호수 안시 | B38: HTL | C38: 디럭스(호텔형) | D38: 132000 | E38: 132000 | F38: 141000 | G38: 197000 | H38: 132000 | I38: 132000 | J38: 132000 | K38: 132000 | L38: 132000 | M38: 141000 | N38: 197000 | O38: 132000 | P38: 132000 | Q38: 132000 | R38: 132000 | S38: 132000 | T38: 141000 | U38: 197000 | V38: 132000 | W38: 132000 | X38: 132000 | Y38: 132000 | Z38: 132000 | AA38: 141000 | AB38: 197000 | AC38: 132000 | AD38: 132000 | AE38: 132000 | AF38: 132000 | AG38: 132000
A39: 산정호수 안시 | B39: FST | C39: 디럭스(싱글트윈) | D39: 132000 | E39: 132000 | F39: 141000 | G39: 197000 | H39: 132000 | I39: 132000 | J39: 132000 | K39: 132000 | L39: 132000 | M39: 141000 | N39: 197000 | O39: 132000 | P39: 132000 | Q39: 132000 | R39: 132000 | S39: 132000 | T39: 141000 | U39: 197000 | V39: 132000 | W39: 132000 | X39: 132000 | Y39: 132000 | Z39: 132000 | AA39: 141000 | AB39: 197000 | AC39: 132000 | AD39: 132000 | AE39: 132000 | AF39: 132000 | AG39: 132000
A40: 산정호수 안시 | B40: RYL | C40: 로얄 | D40: 210000 | E40: 210000 | F40: 225000 | G40: 315000 | H40: 210000 | I40: 210000 | J40: 210000 | K40: 210000 | L40: 210000 | M40: 225000 | N40: 315000 | O40: 210000 | P40: 210000 | Q40: 210000 | R40: 210000 | S40: 210000 | T40: 225000 | U40: 315000 | V40: 210000 | W40: 210000 | X40: 210000 | Y40: 210000 | Z40: 210000 | AA40: 225000 | AB40: 315000 | AC40: 210000 | AD40: 210000 | AE40: 210000 | AF40: 210000 | AG40: 210000
A41: 영업장명 | B41: 객실타입 | C41: 객실명 | D41: 46113 | E41: 46114 | F41: 46115 | G41: 46116 | H41: 46117 | I41: 46118 | J41: 46119 | K41: 46120 | L41: 46121 | M41: 46122 | N41: 46123 | O41: 46124 | P41: 46125 | Q41: 46126 | R41: 46127 | S41: 46128 | T41: 46129 | U41: 46130 | V41: 46131 | W41: 46132 | X41: 46133 | Y41: 46134 | Z41: 46135 | AA41: 46136 | AB41: 46137 | AC41: 46138 | AD41: 46139 | AE41: 46140 | AF41: 46141 | AG41: 46142
D42: =D41 -> 46113 | E42: =E41 -> 46114 | F42: =F41 -> 46115 | G42: =G41 -> 46116 | H42: =H41 -> 46117 | I42: =I41 -> 46118 | J42: =J41 -> 46119 | K42: =K41 -> 46120 | ... AG42: =AG41 -> 46142
...

Sheet 5월(무기명)
A1: ■ 2026년 5월 - 무기명
A2: 영업장명 | B2: 객실타입 | C2: 객실명 | D2: 46143 | E2: 46144 | F2: 46145 | G2: 46146 | H2: 46147 | I2: 46148 | J2: 46149 | K2: 46150 | L2: 46151 | M2: 46152 | N2: 46153 | O2: 46154 | P2: 46155 | Q2: 46156 | R2: 46157 | S2: 46158 | T2: 46159 | U2: 46160 | V2: 46161 | W2: 46162 | X2: 46163 | Y2: 46164 | Z2: 46165 | AA2: 46166 | AB2: 46167 | AC2: 46168 | AD2: 46169 | AE2: 46170 | AF2: 46171 | AG2: 46172 | AH2: 46173
D3: =D2 -> 46143 | E3: =E2 -> 46144 | F3: =F2 -> 46145 | G3: =G2 -> 46146 | H3: =H2 -> 46147 | I3: =I2 -> 46148 | J3: =J2 -> 46149 | K3: =K2 -> 46150 | ... AH3: =AH2 -> 46173
D4: 봄 극성수기 연휴 | E4: 봄 극성수기 연휴 | F4: 봄 극성수기 연휴 | G4: 봄 극성수기 연휴 | H4: 봄 비수기 화요일 | I4: 봄 비수기 수요일 | J4: 봄 비수기 목요일 | K4: 봄 비수기 준주말 | L4: 봄 비수기 주말 | M4: 봄 비수기 일요일 | N4: 봄 비수기 월요일 | O4: 봄 비수기 화요일 | P4: 봄 비수기 수요일 | Q4: 봄 비수기 목요일 | R4: 봄 비수기 준주말 | S4: 봄 비수기 주말 | T4: 봄 비수기 일요일 | U4: 봄 비수기 월요일 | V4: 봄 비수기 화요일 | W4: 봄 비수기 수요일 | X4: 봄 비수기 목요일 | Y4: 봄 극성수기 연휴 | Z4: 봄 극성수기 연휴 | AA4: 봄 극성수기 연휴 | AB4: 봄 비수기 월요일 | AC4: 봄 비수기 화요일 | AD4: 봄 비수기 수요일 | AE4: 봄 비수기 목요일 | AF4: 봄 비수기 준주말 | AG4: 봄 비수기 주말 | AH4: 봄 비수기 일요일
A5: 설악 쏘라노 | B5: FAM | C5: 디럭스 | D5: 241000 | E5: 241000 | F5: 241000 | G5: 241000 | H5: 139000 | I5: 139000 | J5: 139000 | K5: 159000 | L5: 214000 | M5: 139000 | N5: 139000 | O5: 139000 | P5: 139000 | Q5: 139000 | R5: 159000 | S5: 214000 | T5: 139000 | U5: 139000 | V5: 139000 | W5: 139000 | X5: 139000 | Y5: 241000 | Z5: 241000 | AA5: 241000 | AB5: 139000 | AC5: 139000 | AD5: 139000 | AE5: 139000 | AF5: 159000 | AG5: 214000 | AH5: 139000
A6: 설악 쏘라노 | B6: DMO | C6: 디럭스(모던) | D6: 291000 | E6: 291000 | F6: 291000 | G6: 291000 | H6: 169000 | I6: 169000 | J6: 169000 | K6: 209000 | L6: 264000 | M6: 169000 | N6: 169000 | O6: 169000 | P6: 169000 | Q6: 169000 | R6: 209000 | S6: 264000 | T6: 169000 | U6: 169000 | V6: 169000 | W6: 169000 | X6: 169000 | Y6: 291000 | Z6: 291000 | AA6: 291000 | AB6: 169000 | AC6: 169000 | AD6: 169000 | AE6: 169000 | AF6: 209000 | AG6: 264000 | AH6: 169000
A7: 설악 쏘라노 | B7: FSS | C7: 디럭스(원룸) | D7: 241000 | E7: 241000 | F7: 241000 | G7: 241000 | H7: 139000 | I7: 139000 | J7: 139000 | K7: 159000 | L7: 214000 | M7: 139000 | N7: 139000 | O7: 139000 | P7: 139000 | Q7: 139000 | R7: 159000 | S7: 214000 | T7: 139000 | U7: 139000 | V7: 139000 | W7: 139000 | X7: 139000 | Y7: 241000 | Z7: 241000 | AA7: 241000 | AB7: 139000 | AC7: 139000 | AD7: 139000 | AE7: 139000 | AF7: 159000 | AG7: 214000 | AH7: 139000
A8: 설악 쏘라노 | B8: HTE | C8: 디럭스(유러피언_원룸_호텔형) | D8: 301000 | E8: 301000 | F8: 301000 | G8: 301000 | H8: 179000 | I8: 179000 | J8: 179000 | K8: 219000 | L8: 274000 | M8: 179000 | N8: 179000 | O8: 179000 | P8: 179000 | Q8: 179000 | R8: 219000 | S8: 274000 | T8: 179000 | U8: 179000 | V8: 179000 | W8: 179000 | X8: 179000 | Y8: 301000 | Z8: 301000 | AA8: 301000 | AB8: 179000 | AC8: 179000 | AD8: 179000 | AE8: 179000 | AF8: 219000 | AG8: 274000 | AH8: 179000
A9: 설악 쏘라노 | B9: HTL | C9: 디럭스(원룸_호텔형) | D9: 241000 | E9: 241000 | F9: 241000 | G9: 241000 | H9: 139000 | I9: 139000 | J9: 139000 | K9: 159000 | L9: 214000 | M9: 139000 | N9: 139000 | O9: 139000 | P9: 139000 | Q9: 139000 | R9: 159000 | S9: 214000 | T9: 139000 | U9: 139000 | V9: 139000 | W9: 139000 | X9: 139000 | Y9: 241000 | Z9: 241000 | AA9: 241000 | AB9: 139000 | AC9: 139000 | AD9: 139000 | AE9: 139000 | AF9: 159000 | AG9: 214000 | AH9: 139000
A10: 설악 쏘라노 | B10: FTB | C10: 디럭스(트윈베드) | D10: 241000 | E10: 241000 | F10: 241000 | G10: 241000 | H10: 139000 | I10: 139000 | J10: 139000 | K10: 159000 | L10: 214000 | M10: 139000 | N10: 139000 | O10: 139000 | P10: 139000 | Q10: 139000 | R10: 159000 | S10: 214000 | T10: 139000 | U10: 139000 | V10: 139000 | W10: 139000 | X10: 139000 | Y10: 241000 | Z10: 241000 | AA10: 241000 | AB10: 139000 | AC10: 139000 | AD10: 139000 | AE10: 139000 | AF10: 159000 | AG10: 214000 | AH10: 139000
A11: 설악 쏘라노 | B11: FTL | C11: 디럭스(트윈베드_호텔형) | D11: 241000 | E11: 241000 | F11: 241000 | G11: 241000 | H11: 139000 | I11: 139000 | J11: 139000 | K11: 159000 | L11: 214000 | M11: 139000 | N11: 139000 | O11: 139000 | P11: 139000 | Q11: 139000 | R11: 159000 | S11: 214000 | T11: 139000 | U11: 139000 | V11: 139000 | W11: 139000 | X11: 139000 | Y11: 241000 | Z11: 241000 | AA11: 241000 | AB11: 139000 | AC11: 139000 | AD11: 139000 | AE11: 139000 | AF11: 159000 | AG11: 214000 | AH11: 139000
A12: 설악 쏘라노 | B12: TH1 | C12: 디럭스(티니핑 프린세스룸_호텔형) | D12: 301000 | E12: 301000 | F12: 301000 | G12: 301000 | H12: 169000 | I12: 169000 | J12: 169000 | K12: 219000 | L12: 274000 | M12: 169000 | N12: 169000 | O12: 169000 | P12: 169000 | Q12: 169000 | R12: 219000 | S12: 274000 | T12: 169000 | U12: 169000 | V12: 169000 | W12: 169000 | X12: 169000 | Y12: 301000 | Z12: 301000 | AA12: 301000 | AB12: 169000 | AC12: 169000 | AD12: 169000 | AE12: 169000 | AF12: 219000 | AG12: 274000 | AH12: 169000
A13: 설악 쏘라노 | B13: TH2 | C13: 디럭스(티니핑 연구소룸_호텔형) | D13: 301000 | E13: 301000 | F13: 301000 | G13: 301000 | H13: 169000 | I13: 169000 | J13: 169000 | K13: 219000 | L13: 274000 | M13: 169000 | N13: 169000 | O13: 169000 | P13: 169000 | Q13: 169000 | R13: 219000 | S13: 274000 | T13: 169000 | U13: 169000 | V13: 169000 | W13: 169000 | X13: 169000 | Y13: 301000 | Z13: 301000 | AA13: 301000 | AB13: 169000 | AC13: 169000 | AD13: 169000 | AE13: 169000 | AF13: 219000 | AG13: 274000 | AH13: 169000
A14: 설악 쏘라노 | B14: TH3 | C14: 디럭스(티니핑 슈팅스타룸_호텔형) | D14: 301000 | E14: 301000 | F14: 301000 | G14: 301000 | H14: 169000 | I14: 169000 | J14: 169000 | K14: 219000 | L14: 274000 | M14: 169000 | N14: 169000 | O14: 169000 | P14: 169000 | Q14: 169000 | R14: 219000 | S14: 274000 | T14: 169000 | U14: 169000 | V14: 169000 | W14: 169000 | X14: 169000 | Y14: 301000 | Z14: 301000 | AA14: 301000 | AB14: 169000 | AC14: 169000 | AD14: 169000 | AE14: 169000 | AF14: 219000 | AG14: 274000 | AH14: 169000
A15: 설악 쏘라노 | B15: RYL | C15: 로얄 | D15: 386000 | E15: 386000 | F15: 386000 | G15: 386000 | H15: 223000 | I15: 223000 | J15: 223000 | K15: 254000 | L15: 343000 | M15: 223000 | N15: 223000 | O15: 223000 | P15: 223000 | Q15: 223000 | R15: 254000 | S15: 343000 | T15: 223000 | U15: 223000 | V15: 223000 | W15: 223000 | X15: 223000 | Y15: 386000 | Z15: 386000 | AA15: 386000 | AB15: 223000 | AC15: 223000 | AD15: 223000 | AE15: 223000 | AF15: 254000 | AG15: 343000 | AH15: 223000
A16: 설악 쏘라노 | B16: RMO | C16: 로얄(모던) | D16: 436000 | E16: 436000 | F16: 436000 | G16: 436000 | H16: 253000 | I16: 253000 | J16: 253000 | K16: 304000 | L16: 393000 | M16: 253000 | N16: 253000 | O16: 253000 | P16: 253000 | Q16: 253000 | R16: 304000 | S16: 393000 | T16: 253000 | U16: 253000 | V16: 253000 | W16: 253000 | X16: 253000 | Y16: 436000 | Z16: 436000 | AA16: 436000 | AB16: 253000 | AC16: 253000 | AD16: 253000 | AE16: 253000 | AF16: 304000 | AG16: 393000 | AH16: 253000
... A19: 영업장명 | B19: 객실타입 | C19: 객실명 | D19: 46143 | E19: 46144 | F19: 46145 | G19: 46146 | H19: 46147 | I19: 46148 | J19: 46149 | K19: 46150 | L19: 46151 | M19: 46152 | N19: 46153 | O19: 46154 | P19: 46155 | Q19: 46156 | R19: 46157 | S19: 46158 | T19: 46159 | U19: 46160 | V19: 46161 | W19: 46162 | X19: 46163 | Y19: 46164 | Z19: 46165 | AA19: 46166 | AB19: 46167 | AC19: 46168 | AD19: 46169 | AE19: 46170 | AF19: 46171 | AG19: 46172 | AH19: 46173
D20: =D19 -> 46143 | E20: =E19 -> 46144 | F20: =F19 -> 46145 | G20: =G19 -> 46146 | H20: =H19 -> 46147 | I20: =I19 -> 46148 | J20: =J19 -> 46149 | K20: =K19 -> 46150 | ... AH20: =AH19 -> 46173
D21: 봄 극성수기 연휴 | E21: 봄 극성수기 연휴 | F21: 봄 극성수기 연휴 | G21: 봄 극성수기 연휴 | H21: 봄 비수기 화요일 | I21: 봄 비수기 수요일 | J21: 봄 비수기 목요일 | K21: 봄 비수기 준주말 | L21: 봄 비수기 주말 | M21: 봄 비수기 일요일 | N21: 봄 비수기 월요일 | O21: 봄 비수기 화요일 | P21: 봄 비수기 수요일 | Q21: 봄 비수기 목요일 | R21: 봄 비수기 준주말 | S21: 봄 비수기 주말 | T21: 봄 비수기 일요일 | U21: 봄 비수기 월요일 | V21: 봄 비수기 화요일 | W21: 봄 비수기 수요일 | X21: 봄 비수기 목요일 | Y21: 봄 극성수기 연휴 | Z21: 봄 극성수기 연휴 | AA21: 봄 극성수기 연휴 | AB21: 봄 비수기 월요일 | AC21: 봄 비수기 화요일 | AD21: 봄 비수기 수요일 | AE21: 봄 비수기 목요일 | AF21: 봄 비수기 준주말 | AG21: 봄 비수기 주말 | AH21: 봄 비수기 일요일
A22: 설악 별관 | B22: FAM | C22: 디럭스 | D22: 192000 | E22: 192000 | F22: 192000 | G22: 192000 | H22: 123000 | I22: 123000 | J22: 123000 | K22: 136000 | L22: 160000 | M22: 123000 | N22: 123000 | O22: 123000 | P22: 123000 | Q22: 123000 | R22: 136000 | S22: 160000 | T22: 123000 | U22: 123000 | V22: 123000 | W22: 123000 | X22: 123000 | Y22: 192000 | Z22: 192000 | AA22: 192000 | AB22: 123000 | AC22: 123000 | AD22: 123000 | AE22: 123000 | AF22: 136000 | AG22: 160000 | AH22: 123000
A23: 설악 별관 | B23: RYL | C23: 로얄 | D23: 307000 | E23: 307000 | F23: 307000 | G23: 307000 | H23: 197000 | I23: 197000 | J23: 197000 | K23: 218000 | L23: 255000 | M23: 197000 | N23: 197000 | O23: 197000 | P23: 197000 | Q23: 197000 | R23: 218000 | S23: 255000 | T23: 197000 | U23: 197000 | V23: 197000 | W23: 197000 | X23: 197000 | Y23: 307000 | Z23: 307000 | AA23: 307000 | AB23: 197000 | AC23: 197000 | AD23: 197000 | AE23: 197000 | AF23: 218000 | AG23: 255000 | AH23: 197000
A24: 영업장명 | B24: 객실타입 | C24: 객실명 | D24: 46143 | E24: 46144 | F24: 46145 | G24: 46146 | H24: 46147 | I24: 46148 | J24: 46149 | K24: 46150 | L24: 46151 | M24: 46152 | N24: 46153 | O24: 46154 | P24: 46155 | Q24: 46156 | R24: 46157 | S24: 46158 | T24: 46159 | U24: 46160 | V24: 46161 | W24: 46162 | X24: 46163 | Y24: 46164 | Z24: 46165 | AA24: 46166 | AB24: 46167 | AC24: 46168 | AD24: 46169 | AE24: 46170 | AF24: 46171 | AG24: 46172 | AH24: 46173
D25: =D24 -> 46143 | E25: =E24 -> 46144 | F25: =F24 -> 46145 | G25: =G24 -> 46146 | H25: =H24 -> 46147 | I25: =I24 -> 46148 | J25: =J24 -> 46149 | K25: =K24 -> 46150 | ... AH25: =AH24 -> 46173
D26: 봄 극성수기 연휴 | E26: 봄 극성수기 연휴 | F26: 봄 극성수기 연휴 | G26: 봄 극성수기 연휴 | H26: 봄 비수기 화요일 | I26: 봄 비수기 수요일 | J26: 봄 비수기 목요일 | K26: 봄 비수기 준주말 | L26: 봄 비수기 주말 | M26: 봄 비수기 일요일 | N26: 봄 비수기 월요일 | O26: 봄 비수기 화요일 | P26: 봄 비수기 수요일 | Q26: 봄 비수기 목요일 | R26: 봄 비수기 준주말 | S26: 봄 비수기 주말 | T26: 봄 비수기 일요일 | U26: 봄 비수기 월요일 | V26: 봄 비수기 화요일 | W26: 봄 비수기 수요일 | X26: 봄 비수기 목요일 | Y26: 봄 극성수기 연휴 | Z26: 봄 극성수기 연휴 | AA26: 봄 극성수기 연휴 | AB26: 봄 비수기 월요일 | AC26: 봄 비수기 화요일 | AD26: 봄 비수기 수요일 | AE26: 봄 비수기 목요일 | AF26: 봄 비수기 준주말 | AG26: 봄 비수기 주말 | AH26: 봄 비수기 일요일
A27: 용인 베잔송 | B27: FAM | C27: 디럭스 | D27: 232000 | E27: 232000 | F27: 232000 | G27: 232000 | H27: 128000 | I27: 128000 | J27: 128000 | K27: 142000 | L27: 203000 | M27: 128000 | N27: 128000 | O27: 128000 | P27: 128000 | Q27: 128000 | R27: 142000 | S27: 203000 | T27: 128000 | U27: 128000 | V27: 128000 | W27: 128000 | X27: 128000 | Y27: 232000 | Z27: 232000 | AA27: 232000 | AB27: 128000 | AC27: 128000 | AD27: 128000 | AE27: 128000 | AF27: 142000 | AG27: 203000 | AH27: 128000
A28: 용인 베잔송 | B28: HTL | C28: 디럭스(호텔형) | D28: 232000 | E28: 232000 | F28: 232000 | G28: 232000 | H28: 128000 | I28: 128000 | J28: 128000 | K28: 142000 | L28: 203000 | M28: 128000 | N28: 128000 | O28: 128000 | P28: 128000 | Q28: 128000 | R28: 142000 | S28: 203000 | T28: 128000 | U28: 128000 | V28: 128000 | W28: 128000 | X28: 128000 | Y28: 232000 | Z28: 232000 | AA28: 232000 | AB28: 128000 | AC28: 128000 | AD28: 128000 | AE28: 128000 | AF28: 142000 | AG28: 203000 | AH28: 128000
A29: 용인 베잔송 | B29: FST | C29: 디럭스(싱글트윈) | D29: 232000 | E29: 232000 | F29: 232000 | G29: 232000 | H29: 128000 | I29: 128000 | J29: 128000 | K29: 142000 | L29: 203000 | M29: 128000 | N29: 128000 | O29: 128000 | P29: 128000 | Q29: 128000 | R29: 142000 | S29: 203000 | T29: 128000 | U29: 128000 | V29: 128000 | W29: 128000 | X29: 128000 | Y29: 232000 | Z29: 232000 | AA29: 232000 | AB29: 128000 | AC29: 128000 | AD29: 128000 | AE29: 128000 | AF29: 142000 | AG29: 203000 | AH29: 128000
A30: 용인 베잔송 | B30: TH1 | C30: 디럭스(티니핑 프린세스룸_호텔형) | D30: 292000 | E30: 292000 | F30: 292000 | G30: 292000 | H30: 158000 | I30: 158000 | J30: 158000 | K30: 202000 | L30: 263000 | M30: 158000 | N30: 158000 | O30: 158000 | P30: 158000 | Q30: 158000 | R30: 202000 | S30: 263000 | T30: 158000 | U30: 158000 | V30: 158000 | W30: 158000 | X30: 158000 | Y30: 292000 | Z30: 292000 | AA30: 292000 | AB30: 158000 | AC30: 158000 | AD30: 158000 | AE30: 158000 | AF30: 202000 | AG30: 263000 | AH30: 158000
A31: 용인 베잔송 | B31: TH2 | C31: 디럭스(티니핑 연구소룸_호텔형) | D31: 292000 | E31: 292000 | F31: 292000 | G31: 292000 | H31: 158000 | I31: 158000 | J31: 158000 | K31: 202000 | L31: 263000 | M31: 158000 | N31: 158000 | O31: 158000 | P31: 158000 | Q31: 158000 | R31: 202000 | S31: 263000 | T31: 158000 | U31: 158000 | V31: 158000 | W31: 158000 | X31: 158000 | Y31: 292000 | Z31: 292000 | AA31: 292000 | AB31: 158000 | AC31: 158000 | AD31: 158000 | AE31: 158000 | AF31: 202000 | AG31: 263000 | AH31: 158000
A32: 용인 베잔송 | B32: TH3 | C32: 디럭스(티니핑 슈팅스타룸_호텔형) | D32: 292000 | E32: 292000 | F32: 292000 | G32: 292000 | H32: 158000 | I32: 158000 | J32: 158000 | K32: 202000 | L32: 263000 | M32: 158000 | N32: 158000 | O32: 158000 | P32: 158000 | Q32: 158000 | R32: 202000 | S32: 263000 | T32: 158000 | U32: 158000 | V32: 158000 | W32: 158000 | X32: 158000 | Y32: 292000 | Z32: 292000 | AA32: 292000 | AB32: 158000 | AC32: 158000 | AD32: 158000 | AE32: 158000 | AF32: 202000 | AG32: 263000 | AH32: 158000
A33: 용인 베잔송 | B33: RYL | C33: 로얄 | D33: 371000 | E33: 371000 | F33: 371000 | G33: 371000 | H33: 205000 | I33: 205000 | J33: 205000 | K33: 227000 | L33: 325000 | M33: 205000 | N33: 205000 | O33: 205000 | P33: 205000 | Q33: 205000 | R33: 227000 | S33: 325000 | T33: 205000 | U33: 205000 | V33: 205000 | W33: 205000 | X33: 205000 | Y33: 371000 | Z33: 371000 | AA33: 371000 | AB33: 205000 | AC33: 205000 | AD33: 205000 | AE33: 205000 | AF33: 227000 | AG33: 325000 | AH33: 205000
A34: 영업장명 | B34: 객실타입 | C34: 객실명 | D34: 46143 | E34: 46144 | F34: 46145 | G34: 46146 | H34: 46147 | I34: 46148 | J34: 46149 | K34: 46150 | L34: 46151 | M34: 46152 | N34: 46153 | O34: 46154 | P34: 46155 | Q34: 46156 | R34: 46157 | S34: 46158 | T34: 46159 | U34: 46160 | V34: 46161 | W34: 46162 | X34: 46163 | Y34: 46164 | Z34: 46165 | AA34: 46166 | AB34: 46167 | AC34: 46168 | AD34: 46169 | AE34: 46170 | AF34: 46171 | AG34: 46172 | AH34: 46173
D35: =D34 -> 46143 | E35: =E34 -> 46144 | F35: =F34 -> 46145 | G35: =G34 -> 46146 | H35: =H34 -> 46147 | I35: =I34 -> 46148 | J35: =J34 -> 46149 | K35: =K34 -> 46150 | ... AH35: =AH34 -> 46173
D36: 봄 극성수기 연휴 | E36: 봄 극성수기 연휴 | F36: 봄 극성수기 연휴 | G36: 봄 극성수기 연휴 | H36: 봄 비수기 화요일 | I36: 봄 비수기 수요일 | J36: 봄 비수기 목요일 | K36: 봄 비수기 준주말 | L36: 봄 비수기 주말 | M36: 봄 비수기 일요일 | N36: 봄 비수기 월요일 | O36: 봄 비수기 화요일 | P36: 봄 비수기 수요일 | Q36: 봄 비수기 목요일 | R36: 봄 비수기 준주말 | S36: 봄 비수기 주말 | T36: 봄 비수기 일요일 | U36: 봄 비수기 월요일 | V36: 봄 비수기 화요일 | W36: 봄 비수기 수요일 | X36: 봄 비수기 목요일 | Y36: 봄 극성수기 연휴 | Z36: 봄 극성수기 연휴 | AA36: 봄 극성수기 연휴 | AB36: 봄 비수기 월요일 | AC36: 봄 비수기 화요일 | AD36: 봄 비수기 수요일 | AE36: 봄 비수기 목요일 | AF36: 봄 비수기 준주말 | AG36: 봄 비수기 주말 | AH36: 봄 비수기 일요일
A37: 산정호수 안시 | B37: FAM | C37: 디럭스 | D37: 236000 | E37: 236000 | F37: 236000 | G37: 236000 | H37: 132000 | I37: 132000 | J37: 132000 | K37: 141000 | L37: 215000 | M37: 132000 | N37: 132000 | O37: 132000 | P37: 132000 | Q37: 132000 | R37: 141000 | S37: 215000 | T37: 132000 | U37: 132000 | V37: 132000 | W37: 132000 | X37: 132000 | Y37: 236000 | Z37: 236000 | AA37: 236000 | AB37: 132000 | AC37: 132000 | AD37: 132000 | AE37: 132000 | AF37: 141000 | AG37: 215000 | AH37: 132000
A38: 산정호수 안시 | B38: HTL | C38: 디럭스(호텔형) | D38: 236000 | E38: 236000 | F38: 236000 | G38: 236000 | H38: 132000 | I38: 132000 | J38: 132000 | K38: 141000 | L38: 215000 | M38: 132000 | N38: 132000 | O38: 132000 | P38: 132000 | Q38: 132000 | R38: 141000 | S38: 215000 | T38: 132000 | U38: 132000 | V38: 132000 | W38: 132000 | X38: 132000 | Y38: 236000 | Z38: 236000 | AA38: 236000 | AB38: 132000 | AC38: 132000 | AD38: 132000 | AE38: 132000 | AF38: 141000 | AG38: 215000 | AH38: 132000
A39: 산정호수 안시 | B39: FST | C39: 디럭스(싱글트윈) | D39: 236000 | E39: 236000 | F39: 236000 | G39: 236000 | H39: 132000 | I39: 132000 | J39: 132000 | K39: 141000 | L39: 215000 | M39: 132000 | N39: 132000 | O39: 132000 | P39: 132000 | Q39: 132000 | R39: 141000 | S39: 215000 | T39: 132000 | U39: 132000 | V39: 132000 | W39: 132000 | X39: 132000 | Y39: 236000 | Z39: 236000 | AA39: 236000 | AB39: 132000 | AC39: 132000 | AD39: 132000 | AE39: 132000 | AF39: 141000 | AG39: 215000 | AH39: 132000
A40: 산정호수 안시 | B40: RYL | C40: 로얄 | D40: 378000 | E40: 378000 | F40: 378000 | G40: 378000 | H40: 210000 | I40: 210000 | J40: 210000 | K40: 225000 | L40: 345000 | M40: 210000 | N40: 210000 | O40: 210000 | P40: 210000 | Q40: 210000 | R40: 225000 | S40: 345000 | T40: 210000 | U40: 210000 | V40: 210000 | W40: 210000 | X40: 210000 | Y40: 378000 | Z40: 378000 | AA40: 378000 | AB40: 210000 | AC40: 210000 | AD40: 210000 | AE40: 210000 | AF40: 225000 | AG40: 345000 | AH40: 210000
